Workbook

Sheet 주요사이트
B2: 민원관련 사이트
B4: 부산민원
B5: 부산 시민참여예산
B6: 부산 강서구 전자민원
B7: 올댓강서
B8: 부산교육청
B9: 김도읍 의원실
B10: 한국도로공사 (ex.co.kr)
B11: 국토교통부
B12: 부산시청
B13: 강서구청
B14: 디에트르 그랑루체
B15: 부산 에코델타시티

Sheet 카페가입요약
B1: 동별 카페 가입수 현황
F2: =TODAY() -> 46121
B4: 동 | C4: 세대수 | D4: 가입 | E4: 가입률 | F4: 미가입
B5: 201 | C5: =COUNTIFS('동호 코드'!$A$3:$A$1472,카페가입요약!B5) -> 52 | D5: =COUNTIF(raw!$B$2:$B$30000,카페가입요약!B5) -> 12 | E5: =D5/C5 -> 0.23076923 | F5: =C5-D5 -> 40
B6: 202 | C6: =COUNTIFS('동호 코드'!$A$3:$A$1472,카페가입요약!B6) -> 56 | D6: =COUNTIF(raw!$B$2:$B$30000,카페가입요약!B6) -> 11 | E6: =D6/C6 -> 0.19642857 | F6: =C6-D6 -> 45
B7: 203 | C7: =COUNTIFS('동호 코드'!$A$3:$A$1472,카페가입요약!B7) -> 56 | D7: =COUNTIF(raw!$B$2:$B$30000,카페가입요약!B7) -> 18 | E7: =D7/C7 -> 0.32142857 | F7: =C7-D7 -> 38
B8: 204 | C8: =COUNTIFS('동호 코드'!$A$3:$A$1472,카페가입요약!B8) -> 56 | D8: =COUNTIF(raw!$B$2:$B$30000,카페가입요약!B8) -> 14 | E8: =D8/C8 -> 0.25 | F8: =C8-D8 -> 42
B9: 205 | C9: =COUNTIFS('동호 코드'!$A$3:$A$1472,카페가입요약!B9) -> 54 | D9: =COUNTIF(raw!$B$2:$B$30000,카페가입요약!B9) -> 9 | E9: =D9/C9 -> 0.16666667 | F9: =C9-D9 -> 45
B10: 206 | C10: =COUNTIFS('동호 코드'!$A$3:$A$1472,카페가입요약!B10) -> 56 | D10: =COUNTIF(raw!$B$2:$B$30000,카페가입요약!B10) -> 8 | E10: =D10/C10 -> 0.14285714 | F10: =C10-D10 -> 48
B11: 207 | C11: =COUNTIFS('동호 코드'!$A$3:$A$1472,카페가입요약!B11) -> 40 | D11: =COUNTIF(raw!$B$2:$B$30000,카페가입요약!B11) -> 7 | E11: =D11/C11 -> 0.175 | F11: =C11-D11 -> 33
B12: 208 | C12: =COUNTIFS('동호 코드'!$A$3:$A$1472,카페가입요약!B12) -> 38 | D12: =COUNTIF(raw!$B$2:$B$30000,카페가입요약!B12) -> 10 | E12: =D12/C12 -> 0.26315789 | F12: =C12-D12 -> 28
B13: 209 | C13: =COUNTIFS('동호 코드'!$A$3:$A$1472,카페가입요약!B13) -> 41 | D13: =COUNTIF(raw!$B$2:$B$30000,카페가입요약!B13) -> 10 | E13: =D13/C13 -> 0.24390244 | F13: =C13-D13 -> 31
B14: 210 | C14: =COUNTIFS('동호 코드'!$A$3:$A$1472,카페가입요약!B14) -> 51 | D14: =COUNTIF(raw!$B$2:$B$30000,카페가입요약!B14) -> 14 | E14: =D14/C14 -> 0.2745098 | F14: =C14-D14 -> 37
B15: 211 | C15: =COUNTIFS('동호 코드'!$A$3:$A$1472,카페가입요약!B15) -> 37 | D15: =COUNTIF(raw!$B$2:$B$30000,카페가입요약!B15) -> 10 | E15: =D15/C15 -> 0.27027027 | F15: =C15-D15 -> 27
B16: 212 | C16: =COUNTIFS('동호 코드'!$A$3:$A$1472,카페가입요약!B16) -> 56 | D16: =COUNTIF(raw!$B$2:$B$30000,카페가입요약!B16) -> 11 | E16: =D16/C16 -> 0.19642857 | F16: =C16-D16 -> 45
... B31: 227 | C31: =COUNTIFS('동호 코드'!$A$3:$A$1472,카페가입요약!B31) -> 22 | D31: =COUNTIF(raw!$B$2:$B$30000,카페가입요약!B31) -> 12 | E31: =D31/C31 -> 0.54545455 | F31: =C31-D31 -> 10
B32: 합계 | C32: =SUM(C5:C31) -> 1470 | D32: =SUM(D5:D31) -> 309 | E32: =D32/C32 -> 0.21020408 | F32: =C32-D32 -> 1161

Sheet 카페동별상세
B2: 동 | C2: 221
A4: 14 | B4: =IFERROR(INDEX('동호 코드'!$A$3:$E$1472,MATCH(카페동별상세!$C$2&카페동별상세!$B$18&카페동별상세!$A4,'동호 코드'!$E$3:$E$1472, 0),2),"X") -> X | C4: =IF(COUNTIFS(raw!$D$2:$D$29895,카페동별상세!$C$2&카페동별상세!B4)=1,"가입","") | D4: =IFERROR(INDEX('동호 코드'!$A$3:$E$1472,MATCH(카페동별상세!$C$2&카페동별상세!$D$18&카페동별상세!$A4,'동호 코드'!$E$3:$E$1472, 0),2),"X") -> 1402 | E4: =IF(COUNTIFS(raw!$D$2:$D$29895,카페동별상세!$C$2&카페동별상세!D4)=1,"가입","") | F4: =IFERROR(INDEX('동호 코드'!$A$3:$E$1472,MATCH(카페동별상세!$C$2&카페동별상세!$F$18&카페동별상세!$A4,'동호 코드'!$E$3:$E$1472, 0),2),"X") -> 1403 | G4: =IF(COUNTIFS(raw!$D$2:$D$29895,카페동별상세!$C$2&카페동별상세!F4)=1,"가입","") -> 가입 | H4: =IFERROR(INDEX('동호 코드'!$A$3:$E$1472,MATCH(카페동별상세!$C$2&카페동별상세!$H$18&카페동별상세!$A4,'동호 코드'!$E$3:$E$1472, 0),2),"X") -> 1404 | I4: =IF(COUNTIFS(raw!$D$2:$D$29895,카페동별상세!$C$2&카페동별상세!H4)=1,"가입","") -> 가입 | J4: =IFERROR(INDEX('동호 코드'!$A$3:$E$1472,MATCH(카페동별상세!$C$2&카페동별상세!$J$18&카페동별상세!$A4,'동호 코드'!$E$3:$E$1472, 0),2),"X") -> X | K4: =IF(COUNTIFS(raw!$D$2:$D$29895,카페동별상세!$C$2&카페동별상세!J4)=1,"가입","")
A5: 13 | B5: =IFERROR(INDEX('동호 코드'!$A$3:$E$1472,MATCH(카페동별상세!$C$2&카페동별상세!$B$18&카페동별상세!$A5,'동호 코드'!$E$3:$E$1472, 0),2),"X") -> 1301 | C5: =IF(COUNTIFS(raw!$D$2:$D$29895,카페동별상세!$C$2&카페동별상세!B5)=1,"가입","") -> 가입 | D5: =IFERROR(INDEX('동호 코드'!$A$3:$E$1472,MATCH(카페동별상세!$C$2&카페동별상세!$D$18&카페동별상세!$A5,'동호 코드'!$E$3:$E$1472, 0),2),"X") -> 1302 | E5: =IF(COUNTIFS(raw!$D$2:$D$29895,카페동별상세!$C$2&카페동별상세!D5)=1,"가입","") | F5: =IFERROR(INDEX('동호 코드'!$A$3:$E$1472,MATCH(카페동별상세!$C$2&카페동별상세!$F$18&카페동별상세!$A5,'동호 코드'!$E$3:$E$1472, 0),2),"X") -> 1303 | G5: =IF(COUNTIFS(raw!$D$2:$D$29895,카페동별상세!$C$2&카페동별상세!F5)=1,"가입","") | H5: =IFERROR(INDEX('동호 코드'!$A$3:$E$1472,MATCH(카페동별상세!$C$2&카페동별상세!$H$18&카페동별상세!$A5,'동호 코드'!$E$3:$E$1472, 0),2),"X") -> 1304 | I5: =IF(COUNTIFS(raw!$D$2:$D$29895,카페동별상세!$C$2&카페동별상세!H5)=1,"가입","") | J5: =IFERROR(INDEX('동호 코드'!$A$3:$E$1472,MATCH(카페동별상세!$C$2&카페동별상세!$J$18&카페동별상세!$A5,'동호 코드'!$E$3:$E$1472, 0),2),"X") -> X | K5: =IF(COUNTIFS(raw!$D$2:$D$29895,카페동별상세!$C$2&카페동별상세!J5)=1,"가입","")
A6: 12 | B6: =IFERROR(INDEX('동호 코드'!$A$3:$E$1472,MATCH(카페동별상세!$C$2&카페동별상세!$B$18&카페동별상세!$A6,'동호 코드'!$E$3:$E$1472, 0),2),"X") -> 1201 | C6: =IF(COUNTIFS(raw!$D$2:$D$29895,카페동별상세!$C$2&카페동별상세!B6)=1,"가입","") | D6: =IFERROR(INDEX('동호 코드'!$A$3:$E$1472,MATCH(카페동별상세!$C$2&카페동별상세!$D$18&카페동별상세!$A6,'동호 코드'!$E$3:$E$1472, 0),2),"X") -> 1202 | E6: =IF(COUNTIFS(raw!$D$2:$D$29895,카페동별상세!$C$2&카페동별상세!D6)=1,"가입","") | F6: =IFERROR(INDEX('동호 코드'!$A$3:$E$1472,MATCH(카페동별상세!$C$2&카페동별상세!$F$18&카페동별상세!$A6,'동호 코드'!$E$3:$E$1472, 0),2),"X") -> 1203 | G6: =IF(COUNTIFS(raw!$D$2:$D$29895,카페동별상세!$C$2&카페동별상세!F6)=1,"가입","") | H6: =IFERROR(INDEX('동호 코드'!$A$3:$E$1472,MATCH(카페동별상세!$C$2&카페동별상세!$H$18&카페동별상세!$A6,'동호 코드'!$E$3:$E$1472, 0),2),"X") -> 1204 | I6: =IF(COUNTIFS(raw!$D$2:$D$29895,카페동별상세!$C$2&카페동별상세!H6)=1,"가입","") | J6: =IFERROR(INDEX('동호 코드'!$A$3:$E$1472,MATCH(카페동별상세!$C$2&카페동별상세!$J$18&카페동별상세!$A6,'동호 코드'!$E$3:$E$1472, 0),2),"X") -> X | K6: =IF(COUNTIFS(raw!$D$2:$D$29895,카페동별상세!$C$2&카페동별상세!J6)=1,"가입","")
A7: 11 | B7: =IFERROR(INDEX('동호 코드'!$A$3:$E$1472,MATCH(카페동별상세!$C$2&카페동별상세!$B$18&카페동별상세!$A7,'동호 코드'!$E$3:$E$1472, 0),2),"X") -> 1101 | C7: =IF(COUNTIFS(raw!$D$2:$D$29895,카페동별상세!$C$2&카페동별상세!B7)=1,"가입","") | D7: =IFERROR(INDEX('동호 코드'!$A$3:$E$1472,MATCH(카페동별상세!$C$2&카페동별상세!$D$18&카페동별상세!$A7,'동호 코드'!$E$3:$E$1472, 0),2),"X") -> 1102 | E7: =IF(COUNTIFS(raw!$D$2:$D$29895,카페동별상세!$C$2&카페동별상세!D7)=1,"가입","") | F7: =IFERROR(INDEX('동호 코드'!$A$3:$E$1472,MATCH(카페동별상세!$C$2&카페동별상세!$F$18&카페동별상세!$A7,'동호 코드'!$E$3:$E$1472, 0),2),"X") -> 1103 | G7: =IF(COUNTIFS(raw!$D$2:$D$29895,카페동별상세!$C$2&카페동별상세!F7)=1,"가입","") | H7: =IFERROR(INDEX('동호 코드'!$A$3:$E$1472,MATCH(카페동별상세!$C$2&카페동별상세!$H$18&카페동별상세!$A7,'동호 코드'!$E$3:$E$1472, 0),2),"X") -> 1104 | I7: =IF(COUNTIFS(raw!$D$2:$D$29895,카페동별상세!$C$2&카페동별상세!H7)=1,"가입","") | J7: =IFERROR(INDEX('동호 코드'!$A$3:$E$1472,MATCH(카페동별상세!$C$2&카페동별상세!$J$18&카페동별상세!$A7,'동호 코드'!$E$3:$E$1472, 0),2),"X") -> X | K7: =IF(COUNTIFS(raw!$D$2:$D$29895,카페동별상세!$C$2&카페동별상세!J7)=1,"가입","")
A8: 10 | B8: =IFERROR(INDEX('동호 코드'!$A$3:$E$1472,MATCH(카페동별상세!$C$2&카페동별상세!$B$18&카페동별상세!$A8,'동호 코드'!$E$3:$E$1472, 0),2),"X") -> 1001 | C8: =IF(COUNTIFS(raw!$D$2:$D$29895,카페동별상세!$C$2&카페동별상세!B8)=1,"가입","") | D8: =IFERROR(INDEX('동호 코드'!$A$3:$E$1472,MATCH(카페동별상세!$C$2&카페동별상세!$D$18&카페동별상세!$A8,'동호 코드'!$E$3:$E$1472, 0),2),"X") -> 1002 | E8: =IF(COUNTIFS(raw!$D$2:$D$29895,카페동별상세!$C$2&카페동별상세!D8)=1,"가입","") | F8: =IFERROR(INDEX('동호 코드'!$A$3:$E$1472,MATCH(카페동별상세!$C$2&카페동별상세!$F$18&카페동별상세!$A8,'동호 코드'!$E$3:$E$1472, 0),2),"X") -> 1003 | G8: =IF(COUNTIFS(raw!$D$2:$D$29895,카페동별상세!$C$2&카페동별상세!F8)=1,"가입","") | H8: =IFERROR(INDEX('동호 코드'!$A$3:$E$1472,MATCH(카페동별상세!$C$2&카페동별상세!$H$18&카페동별상세!$A8,'동호 코드'!$E$3:$E$1472, 0),2),"X") -> 1004 | I8: =IF(COUNTIFS(raw!$D$2:$D$29895,카페동별상세!$C$2&카페동별상세!H8)=1,"가입","") | J8: =IFERROR(INDEX('동호 코드'!$A$3:$E$1472,MATCH(카페동별상세!$C$2&카페동별상세!$J$18&카페동별상세!$A8,'동호 코드'!$E$3:$E$1472, 0),2),"X") -> X | K8: =IF(COUNTIFS(raw!$D$2:$D$29895,카페동별상세!$C$2&카페동별상세!J8)=1,"가입","")
A9: 9 | B9: =IFERROR(INDEX('동호 코드'!$A$3:$E$1472,MATCH(카페동별상세!$C$2&카페동별상세!$B$18&카페동별상세!$A9,'동호 코드'!$E$3:$E$1472, 0),2),"X") -> 901 | C9: =IF(COUNTIFS(raw!$D$2:$D$29895,카페동별상세!$C$2&카페동별상세!B9)=1,"가입","") | D9: =IFERROR(INDEX('동호 코드'!$A$3:$E$1472,MATCH(카페동별상세!$C$2&카페동별상세!$D$18&카페동별상세!$A9,'동호 코드'!$E$3:$E$1472, 0),2),"X") -> 902 | E9: =IF(COUNTIFS(raw!$D$2:$D$29895,카페동별상세!$C$2&카페동별상세!D9)=1,"가입","") | F9: =IFERROR(INDEX('동호 코드'!$A$3:$E$1472,MATCH(카페동별상세!$C$2&카페동별상세!$F$18&카페동별상세!$A9,'동호 코드'!$E$3:$E$1472, 0),2),"X") -> 903 | G9: =IF(COUNTIFS(raw!$D$2:$D$29895,카페동별상세!$C$2&카페동별상세!F9)=1,"가입","") | H9: =IFERROR(INDEX('동호 코드'!$A$3:$E$1472,MATCH(카페동별상세!$C$2&카페동별상세!$H$18&카페동별상세!$A9,'동호 코드'!$E$3:$E$1472, 0),2),"X") -> 904 | I9: =IF(COUNTIFS(raw!$D$2:$D$29895,카페동별상세!$C$2&카페동별상세!H9)=1,"가입","") -> 가입 | J9: =IFERROR(INDEX('동호 코드'!$A$3:$E$1472,MATCH(카페동별상세!$C$2&카페동별상세!$J$18&카페동별상세!$A9,'동호 코드'!$E$3:$E$1472, 0),2),"X") -> X | K9: =IF(COUNTIFS(raw!$D$2:$D$29895,카페동별상세!$C$2&카페동별상세!J9)=1,"가입","")
A10: 8 | B10: =IFERROR(INDEX('동호 코드'!$A$3:$E$1472,MATCH(카페동별상세!$C$2&카페동별상세!$B$18&카페동별상세!$A10,'동호 코드'!$E$3:$E$1472, 0),2),"X") -> 801 | C10: =IF(COUNTIFS(raw!$D$2:$D$29895,카페동별상세!$C$2&카페동별상세!B10)=1,"가입","") | D10: =IFERROR(INDEX('동호 코드'!$A$3:$E$1472,MATCH(카페동별상세!$C$2&카페동별상세!$D$18&카페동별상세!$A10,'동호 코드'!$E$3:$E$1472, 0),2),"X") -> 802 | E10: =IF(COUNTIFS(raw!$D$2:$D$29895,카페동별상세!$C$2&카페동별상세!D10)=1,"가입","") | F10: =IFERROR(INDEX('동호 코드'!$A$3:$E$1472,MATCH(카페동별상세!$C$2&카페동별상세!$F$18&카페동별상세!$A10,'동호 코드'!$E$3:$E$1472, 0),2),"X") -> 803 | G10: =IF(COUNTIFS(raw!$D$2:$D$29895,카페동별상세!$C$2&카페동별상세!F10)=1,"가입","") | H10: =IFERROR(INDEX('동호 코드'!$A$3:$E$1472,MATCH(카페동별상세!$C$2&카페동별상세!$H$18&카페동별상세!$A10,'동호 코드'!$E$3:$E$1472, 0),2),"X") -> 804 | I10: =IF(COUNTIFS(raw!$D$2:$D$29895,카페동별상세!$C$2&카페동별상세!H10)=1,"가입","") | J10: =IFERROR(INDEX('동호 코드'!$A$3:$E$1472,MATCH(카페동별상세!$C$2&카페동별상세!$J$18&카페동별상세!$A10,'동호 코드'!$E$3:$E$1472, 0),2),"X") -> X | K10: =IF(COUNTIFS(raw!$D$2:$D$29895,카페동별상세!$C$2&카페동별상세!J10)=1,"가입","")
A11: 7 | B11: =IFERROR(INDEX('동호 코드'!$A$3:$E$1472,MATCH(카페동별상세!$C$2&카페동별상세!$B$18&카페동별상세!$A11,'동호 코드'!$E$3:$E$1472, 0),2),"X") -> 701 | C11: =IF(COUNTIFS(raw!$D$2:$D$29895,카페동별상세!$C$2&카페동별상세!B11)=1,"가입","") | D11: =IFERROR(INDEX('동호 코드'!$A$3:$E$1472,MATCH(카페동별상세!$C$2&카페동별상세!$D$18&카페동별상세!$A11,'동호 코드'!$E$3:$E$1472, 0),2),"X") -> 702 | E11: =IF(COUNTIFS(raw!$D$2:$D$29895,카페동별상세!$C$2&카페동별상세!D11)=1,"가입","") | F11: =IFERROR(INDEX('동호 코드'!$A$3:$E$1472,MATCH(카페동별상세!$C$2&카페동별상세!$F$18&카페동별상세!$A11,'동호 코드'!$E$3:$E$1472, 0),2),"X") -> 703 | G11: =IF(COUNTIFS(raw!$D$2:$D$29895,카페동별상세!$C$2&카페동별상세!F11)=1,"가입","") | H11: =IFERROR(INDEX('동호 코드'!$A$3:$E$1472,MATCH(카페동별상세!$C$2&카페동별상세!$H$18&카페동별상세!$A11,'동호 코드'!$E$3:$E$1472, 0),2),"X") -> 704 | I11: =IF(COUNTIFS(raw!$D$2:$D$29895,카페동별상세!$C$2&카페동별상세!H11)=1,"가입","") | J11: =IFERROR(INDEX('동호 코드'!$A$3:$E$1472,MATCH(카페동별상세!$C$2&카페동별상세!$J$18&카페동별상세!$A11,'동호 코드'!$E$3:$E$1472, 0),2),"X") -> X | K11: =IF(COUNTIFS(raw!$D$2:$D$29895,카페동별상세!$C$2&카페동별상세!J11)=1,"가입","")
A12: 6 | B12: =IFERROR(INDEX('동호 코드'!$A$3:$E$1472,MATCH(카페동별상세!$C$2&카페동별상세!$B$18&카페동별상세!$A12,'동호 코드'!$E$3:$E$1472, 0),2),"X") -> 601 | C12: =IF(COUNTIFS(raw!$D$2:$D$29895,카페동별상세!$C$2&카페동별상세!B12)=1,"가입","") | D12: =IFERROR(INDEX('동호 코드'!$A$3:$E$1472,MATCH(카페동별상세!$C$2&카페동별상세!$D$18&카페동별상세!$A12,'동호 코드'!$E$3:$E$1472, 0),2),"X") -> 602 | E12: =IF(COUNTIFS(raw!$D$2:$D$29895,카페동별상세!$C$2&카페동별상세!D12)=1,"가입","") | F12: =IFERROR(INDEX('동호 코드'!$A$3:$E$1472,MATCH(카페동별상세!$C$2&카페동별상세!$F$18&카페동별상세!$A12,'동호 코드'!$E$3:$E$1472, 0),2),"X") -> 603 | G12: =IF(COUNTIFS(raw!$D$2:$D$29895,카페동별상세!$C$2&카페동별상세!F12)=1,"가입","") | H12: =IFERROR(INDEX('동호 코드'!$A$3:$E$1472,MATCH(카페동별상세!$C$2&카페동별상세!$H$18&카페동별상세!$A12,'동호 코드'!$E$3:$E$1472, 0),2),"X") -> 604 | I12: =IF(COUNTIFS(raw!$D$2:$D$29895,카페동별상세!$C$2&카페동별상세!H12)=1,"가입","") -> 가입 | J12: =IFERROR(INDEX('동호 코드'!$A$3:$E$1472,MATCH(카페동별상세!$C$2&카페동별상세!$J$18&카페동별상세!$A12,'동호 코드'!$E$3:$E$1472, 0),2),"X") -> X | K12: =IF(COUNTIFS(raw!$D$2:$D$29895,카페동별상세!$C$2&카페동별상세!J12)=1,"가입","")
A13: 5 | B13: =IFERROR(INDEX('동호 코드'!$A$3:$E$1472,MATCH(카페동별상세!$C$2&카페동별상세!$B$18&카페동별상세!$A13,'동호 코드'!$E$3:$E$1472, 0),2),"X") -> 501 | C13: =IF(COUNTIFS(raw!$D$2:$D$29895,카페동별상세!$C$2&카페동별상세!B13)=1,"가입","") | D13: =IFERROR(INDEX('동호 코드'!$A$3:$E$1472,MATCH(카페동별상세!$C$2&카페동별상세!$D$18&카페동별상세!$A13,'동호 코드'!$E$3:$E$1472, 0),2),"X") -> 502 | E13: =IF(COUNTIFS(raw!$D$2:$D$29895,카페동별상세!$C$2&카페동별상세!D13)=1,"가입","") -> 가입 | F13: =IFERROR(INDEX('동호 코드'!$A$3:$E$1472,MATCH(카페동별상세!$C$2&카페동별상세!$F$18&카페동별상세!$A13,'동호 코드'!$E$3:$E$1472, 0),2),"X") -> 503 | G13: =IF(COUNTIFS(raw!$D$2:$D$29895,카페동별상세!$C$2&카페동별상세!F13)=1,"가입","") | H13: =IFERROR(INDEX('동호 코드'!$A$3:$E$1472,MATCH(카페동별상세!$C$2&카페동별상세!$H$18&카페동별상세!$A13,'동호 코드'!$E$3:$E$1472, 0),2),"X") -> 504 | I13: =IF(COUNTIFS(raw!$D$2:$D$29895,카페동별상세!$C$2&카페동별상세!H13)=1,"가입","") -> 가입 | J13: =IFERROR(INDEX('동호 코드'!$A$3:$E$1472,MATCH(카페동별상세!$C$2&카페동별상세!$J$18&카페동별상세!$A13,'동호 코드'!$E$3:$E$1472, 0),2),"X") -> X | K13: =IF(COUNTIFS(raw!$D$2:$D$29895,카페동별상세!$C$2&카페동별상세!J13)=1,"가입","")
A14: 4 | B14: =IFERROR(INDEX('동호 코드'!$A$3:$E$1472,MATCH(카페동별상세!$C$2&카페동별상세!$B$18&카페동별상세!$A14,'동호 코드'!$E$3:$E$1472, 0),2),"X") -> 401 | C14: =IF(COUNTIFS(raw!$D$2:$D$29895,카페동별상세!$C$2&카페동별상세!B14)=1,"가입","") | D14: =IFERROR(INDEX('동호 코드'!$A$3:$E$1472,MATCH(카페동별상세!$C$2&카페동별상세!$D$18&카페동별상세!$A14,'동호 코드'!$E$3:$E$1472, 0),2),"X") -> 402 | E14: =IF(COUNTIFS(raw!$D$2:$D$29895,카페동별상세!$C$2&카페동별상세!D14)=1,"가입","") | F14: =IFERROR(INDEX('동호 코드'!$A$3:$E$1472,MATCH(카페동별상세!$C$2&카페동별상세!$F$18&카페동별상세!$A14,'동호 코드'!$E$3:$E$1472, 0),2),"X") -> 403 | G14: =IF(COUNTIFS(raw!$D$2:$D$29895,카페동별상세!$C$2&카페동별상세!F14)=1,"가입","") | H14: =IFERROR(INDEX('동호 코드'!$A$3:$E$1472,MATCH(카페동별상세!$C$2&카페동별상세!$H$18&카페동별상세!$A14,'동호 코드'!$E$3:$E$1472, 0),2),"X") -> 404 | I14: =IF(COUNTIFS(raw!$D$2:$D$29895,카페동별상세!$C$2&카페동별상세!H14)=1,"가입","") | J14: =IFERROR(INDEX('동호 코드'!$A$3:$E$1472,MATCH(카페동별상세!$C$2&카페동별상세!$J$18&카페동별상세!$A14,'동호 코드'!$E$3:$E$1472, 0),2),"X") -> X | K14: =IF(COUNTIFS(raw!$D$2:$D$29895,카페동별상세!$C$2&카페동별상세!J14)=1,"가입","")
A15: 3 | B15: =IFERROR(INDEX('동호 코드'!$A$3:$E$1472,MATCH(카페동별상세!$C$2&카페동별상세!$B$18&카페동별상세!$A15,'동호 코드'!$E$3:$E$1472, 0),2),"X") -> 301 | C15: =IF(COUNTIFS(raw!$D$2:$D$29895,카페동별상세!$C$2&카페동별상세!B15)=1,"가입","") | D15: =IFERROR(INDEX('동호 코드'!$A$3:$E$1472,MATCH(카페동별상세!$C$2&카페동별상세!$D$18&카페동별상세!$A15,'동호 코드'!$E$3:$E$1472, 0),2),"X") -> 302 | E15: =IF(COUNTIFS(raw!$D$2:$D$29895,카페동별상세!$C$2&카페동별상세!D15)=1,"가입","") | F15: =IFERROR(INDEX('동호 코드'!$A$3:$E$1472,MATCH(카페동별상세!$C$2&카페동별상세!$F$18&카페동별상세!$A15,'동호 코드'!$E$3:$E$1472, 0),2),"X") -> 303 | G15: =IF(COUNTIFS(raw!$D$2:$D$29895,카페동별상세!$C$2&카페동별상세!F15)=1,"가입","") | H15: =IFERROR(INDEX('동호 코드'!$A$3:$E$1472,MATCH(카페동별상세!$C$2&카페동별상세!$H$18&카페동별상세!$A15,'동호 코드'!$E$3:$E$1472, 0),2),"X") -> 304 | I15: =IF(COUNTIFS(raw!$D$2:$D$29895,카페동별상세!$C$2&카페동별상세!H15)=1,"가입","") | J15: =IFERROR(INDEX('동호 코드'!$A$3:$E$1472,MATCH(카페동별상세!$C$2&카페동별상세!$J$18&카페동별상세!$A15,'동호 코드'!$E$3:$E$1472, 0),2),"X") -> X | K15: =IF(COUNTIFS(raw!$D$2:$D$29895,카페동별상세!$C$2&카페동별상세!J15)=1,"가입","")
... A17: 1 | B17: =IFERROR(INDEX('동호 코드'!$A$3:$E$1472,MATCH(카페동별상세!$C$2&카페동별상세!$B$18&카페동별상세!$A17,'동호 코드'!$E$3:$E$1472, 0),2),"X") -> 101 | C17: =IF(COUNTIFS(raw!$D$2:$D$29895,카페동별상세!$C$2&카페동별상세!B17)=1,"가입","") | D17: =IFERROR(INDEX('동호 코드'!$A$3:$E$1472,MATCH(카페동별상세!$C$2&카페동별상세!$D$18&카페동별상세!$A17,'동호 코드'!$E$3:$E$1472, 0),2),"X") -> 102 | E17: =IF(COUNTIFS(raw!$D$2:$D$29895,카페동별상세!$C$2&카페동별상세!D17)=1,"가입","") -> 가입 | F17: =IFERROR(INDEX('동호 코드'!$A$3:$E$1472,MATCH(카페동별상세!$C$2&카페동별상세!$F$18&카페동별상세!$A17,'동호 코드'!$E$3:$E$1472, 0),2),"X") -> 103 | G17: =IF(COUNTIFS(raw!$D$2:$D$29895,카페동별상세!$C$2&카페동별상세!F17)=1,"가입","") | H17: =IFERROR(INDEX('동호 코드'!$A$3:$E$1472,MATCH(카페동별상세!$C$2&카페동별상세!$H$18&카페동별상세!$A17,'동호 코드'!$E$3:$E$1472, 0),2),"X") -> 104 | I17: =IF(COUNTIFS(raw!$D$2:$D$29895,카페동별상세!$C$2&카페동별상세!H17)=1,"가입","") | J17: =IFERROR(INDEX('동호 코드'!$A$3:$E$1472,MATCH(카페동별상세!$C$2&카페동별상세!$J$18&카페동별상세!$A17,'동호 코드'!$E$3:$E$1472, 0),2),"X") -> X | K17: =IF(COUNTIFS(raw!$D$2:$D$29895,카페동별상세!$C$2&카페동별상세!J17)=1,"가입","")
B18: 1호 | D18: 2호 | F18: 3호 | H18: 4호 | J18: 5호
B19: =VLOOKUP($C$2,'동호 코드'!$J$3:$O$29,2) -> 84A | C19: =VLOOKUP($C$2,'동호 코드'!$J$3:$O$29,2) -> 84A | D19: =VLOOKUP($C$2,'동호 코드'!$J$3:$O$29,3) -> 84A | E19: =VLOOKUP($C$2,'동호 코드'!$J$3:$O$29,2) -> 84A | F19: =VLOOKUP($C$2,'동호 코드'!$J$3:$O$29,4) -> 84B | G19: =VLOOKUP($C$2,'동호 코드'!$J$3:$O$29,2) -> 84A | H19: =VLOOKUP($C$2,'동호 코드'!$J$3:$O$29,5) -> 84B | I19: =VLOOKUP($C$2,'동호 코드'!$J$3:$O$29,2) -> 84A | J19: =VLOOKUP($C$2,'동호 코드'!$J$3:$O$29,6) -> 0

Sheet raw
B1: 동 | C1: 호
B2: 212 | C2: 1101 | D2: =B2&C2 -> 2121101
B3: 210 | C3: 1201 | D3: =B3&C3 -> 2101201
B4: 208 | C4: 503 | D4: =B4&C4 -> 208503
B5: 224 | C5: 1403 | D5: =B5&C5 -> 2241403
B6: 203 | C6: 1104 | D6: =B6&C6 -> 2031104
B7: 222 | C7: 1404 | D7: =B7&C7 -> 2221404
B8: 213 | C8: 501 | D8: =B8&C8 -> 213501
B9: 207 | C9: 1401 | D9: =B9&C9 -> 2071401
B10: 213 | C10: 1305 | D10: =B10&C10 -> 2131305
B11: 213 | C11: 504 | D11: =B11&C11 -> 213504
B12: 215 | C12: 1304 | D12: =B12&C12 -> 2151304
B13: 203 | C13: 1403 | D13: =B13&C13 -> 2031403
... B264: 214 | C264: 101 | D264: =B264&C264 -> 214101
B265: 213 | C265: 404 | D265: =B265&C265 -> 213404
B266: 217 | C266: 803 | D266: =B266&C266 -> 217803
B267: 202 | C267: 501 | D267: =B267&C267 -> 202501
B268: 222 | C268: 1003 | D268: =B268&C268 -> 2221003
B269: 204 | C269: 1103 | D269: =B269&C269 -> 2041103
B270: 214 | C270: 1201 | D270: =B270&C270 -> 2141201
B271: 214 | C271: 703 | D271: =B271&C271 -> 214703
B272: 201 | C272: 704 | D272: =B272&C272 -> 201704
B273: 223 | C273: 1205 | D273: =B273&C273 -> 2231205
B274: 217 | C274: 404 | D274: =B274&C274 -> 217404
B275: 208 | C275: 1101 | D275: =B275&C275 -> 2081101
B276: 221 | C276: 604 | D276: =B276&C276 -> 221604
... B311: 219 | C311: 203 | D311: =B311&C311 -> 219203

Sheet 동호 코드
B1: =SUBTOTAL(2,B3:B1472) -> 1470
A2: 동 | B2: 호 | K2: 1호 | L2: 2호 | M2: 3호 | N2: 4호 | O2: 5호
A3: 201 | B3: 103 | C3: =RIGHT(B3,1)&"호" -> 3호 | D3: =LEFT(B3,1) -> 1 | E3: =A3&C3&D3 -> 2013호1 | J3: 201 | K3: 110A | L3: 110B | M3: 110B | N3: 110A
A4: 201 | B4: 104 | C4: =RIGHT(B4,1)&"호" -> 4호 | D4: =LEFT(B4,1) -> 1 | E4: =A4&C4&D4 -> 2014호1 | J4: 202 | K4: 110A | L4: 110B | M4: 110B | N4: 110A
A5: 201 | B5: 203 | C5: =RIGHT(B5,1)&"호" -> 3호 | D5: =LEFT(B5,1) -> 2 | E5: =A5&C5&D5 -> 2013호2 | J5: 203 | K5: 110A | L5: 110B | M5: 110B | N5: 110A
A6: 201 | B6: 204 | C6: =RIGHT(B6,1)&"호" -> 4호 | D6: =LEFT(B6,1) -> 2 | E6: =A6&C6&D6 -> 2014호2 | J6: 204 | K6: 110A | L6: 110B | M6: 110B | N6: 110A
A7: 201 | B7: 301 | C7: =RIGHT(B7,1)&"호" -> 1호 | D7: =LEFT(B7,1) -> 3 | E7: =A7&C7&D7 -> 2011호3 | J7: 205 | K7: 110A | L7: 110B | M7: 110B | N7: 110A
A8: 201 | B8: 302 | C8: =RIGHT(B8,1)&"호" -> 2호 | D8: =LEFT(B8,1) -> 3 | E8: =A8&C8&D8 -> 2012호3 | J8: 206 | K8: 110A | L8: 110B | M8: 110B | N8: 110A
A9: 201 | B9: 303 | C9: =RIGHT(B9,1)&"호" -> 3호 | D9: =LEFT(B9,1) -> 3 | E9: =A9&C9&D9 -> 2013호3 | J9: 207 | K9: 59A | L9: 59B | M9: 59A
A10: 201 | B10: 304 | C10: =RIGHT(B10,1)&"호" -> 4호 | D10: =LEFT(B10,1) -> 3 | E10: =A10&C10&D10 -> 2014호3 | J10: 208 | K10: 59A | L10: 59B | M10: 59A
A11: 201 | B11: 401 | C11: =RIGHT(B11,1)&"호" -> 1호 | D11: =LEFT(B11,1) -> 4 | E11: =A11&C11&D11 -> 2011호4 | J11: 209 | K11: 110A | L11: 110B | M11: 110A
A12: 201 | B12: 402 | C12: =RIGHT(B12,1)&"호" -> 2호 | D12: =LEFT(B12,1) -> 4 | E12: =A12&C12&D12 -> 2012호4 | J12: 210 | K12: 59A | L12: 59B | M12: 59B | N12: 59A
A13: 201 | B13: 403 | C13: =RIGHT(B13,1)&"호" -> 3호 | D13: =LEFT(B13,1) -> 4 | E13: =A13&C13&D13 -> 2013호4 | J13: 211 | K13: 59A | L13: 59B | M13: 59B | N13: 59A
A14: 201 | B14: 404 | C14: =RIGHT(B14,1)&"호" -> 4호 | D14: =LEFT(B14,1) -> 4 | E14: =A14&C14&D14 -> 2014호4 | J14: 212 | K14: 59A | L14: 59B | M14: 59B | N14: 59A
A15: 201 | B15: 501 | C15: =RIGHT(B15,1)&"호" -> 1호 | D15: =LEFT(B15,1) -> 5 | E15: =A15&C15&D15 -> 2011호5 | J15: 213 | K15: 59A | L15: 59A | M15: 59B | N15: 59B | O15: 59A
A16: 201 | B16: 502 | C16: =RIGHT(B16,1)&"호" -> 2호 | D16: =LEFT(B16,1) -> 5 | E16: =A16&C16&D16 -> 2012호5 | J16: 214 | K16: 84A | L16: 84B | M16: 84B | N16: 84A | O16: 84A
A17: 201 | B17: 503 | C17: =RIGHT(B17,1)&"호" -> 3호 | D17: =LEFT(B17,1) -> 5 | E17: =A17&C17&D17 -> 2013호5 | J17: 215 | K17: 84A | L17: 84B | M17: 84B | N17: 84A | O17: 84A
A18: 201 | B18: 504 | C18: =RIGHT(B18,1)&"호" -> 4호 | D18: =LEFT(B18,1) -> 5 | E18: =A18&C18&D18 -> 2014호5 | J18: 216 | K18: 84A | L18: 84A | M18: 84B | N18: 84B | O18: 84A
A19: 201 | B19: 601 | C19: =RIGHT(B19,1)&"호" -> 1호 | D19: =LEFT(B19,1) -> 6 | E19: =A19&C19&D19 -> 2011호6 | J19: 217 | K19: 84A | L19: 84B | M19: 84B | N19: 84A
A20: 201 | B20: 602 | C20: =RIGHT(B20,1)&"호" -> 2호 | D20: =LEFT(B20,1) -> 6 | E20: =A20&C20&D20 -> 2012호6 | J20: 218 | K20: 84A | L20: 84B | M20: 84B | N20: 84A
A21: 201 | B21: 603 | C21: =RIGHT(B21,1)&"호" -> 3호 | D21: =LEFT(B21,1) -> 6 | E21: =A21&C21&D21 -> 2013호6 | J21: 219 | K21: 84A | L21: 84A | M21: 84B | N21: 84B | O21: 84A
A22: 201 | B22: 604 | C22: =RIGHT(B22,1)&"호" -> 4호 | D22: =LEFT(B22,1) -> 6 | E22: =A22&C22&D22 -> 2014호6 | J22: 220 | K22: 84A | L22: 84A | M22: 84B | N22: 84B | O22: 84A
A23: 201 | B23: 701 | C23: =RIGHT(B23,1)&"호" -> 1호 | D23: =LEFT(B23,1) -> 7 | E23: =A23&C23&D23 -> 2011호7 | J23: 221 | K23: 84A | L23: 84A | M23: 84B | N23: 84B
A24: 201 | B24: 702 | C24: =RIGHT(B24,1)&"호" -> 2호 | D24: =LEFT(B24,1) -> 7 | E24: =A24&C24&D24 -> 2012호7 | J24: 222 | K24: 84A | L24: 84A | M24: 84B | N24: 84B
A25: 201 | B25: 703 | C25: =RIGHT(B25,1)&"호" -> 3호 | D25: =LEFT(B25,1) -> 7 | E25: =A25&C25&D25 -> 2013호7 | J25: 223 | K25: 84A | L25: 84A | M25: 84B | N25: 84B | O25: 84A
A26: 201 | B26: 704 | C26: =RIGHT(B26,1)&"호" -> 4호 | D26: =LEFT(B26,1) -> 7 | E26: =A26&C26&D26 -> 2014호7 | J26: 224 | K26: 84A | L26: 84A | M26: 84B | N26: 84B | O26: 84A
A27: 201 | B27: 801 | C27: =RIGHT(B27,1)&"호" -> 1호 | D27: =LEFT(B27,1) -> 8 | E27: =A27&C27&D27 -> 2011호8 | J27: 225 | K27: 84A | L27: 84B | M27: 84B | N27: 84A
A28: 201 | B28: 802 | C28: =RIGHT(B28,1)&"호" -> 2호 | D28: =LEFT(B28,1) -> 8 | E28: =A28&C28&D28 -> 2012호8 | J28: 226 | K28: 84A | L28: 84A | M28: 84B | N28: 84B | O28: 84A
A29: 201 | B29: 803 | C29: =RIGHT(B29,1)&"호" -> 3호 | D29: =LEFT(B29,1) -> 8 | E29: =A29&C29&D29 -> 2013호8 | J29: 227 | K29: 84A | L29: 84A
A30: 201 | B30: 804 | C30: =RIGHT(B30,1)&"호" -> 4호 | D30: =LEFT(B30,1) -> 8 | E30: =A30&C30&D30 -> 2014호8
A31: 201 | B31: 901 | C31: =RIGHT(B31,1)&"호" -> 1호 | D31: =LEFT(B31,1) -> 9 | E31: =A31&C31&D31 -> 2011호9
A32: 201 | B32: 902 | C32: =RIGHT(B32,1)&"호" -> 2호 | D32: =LEFT(B32,1) -> 9 | E32: =A32&C32&D32 -> 2012호9 | J32: 59A | K32: 165
A33: 201 | B33: 903 | C33: =RIGHT(B33,1)&"호" -> 3호 | D33: =LEFT(B33,1) -> 9 | E33: =A33&C33&D33 -> 2013호9 | J33: 59B | K33: 124
A34: 201 | B34: 904 | C34: =RIGHT(B34,1)&"호" -> 4호 | D34: =LEFT(B34,1) -> 9 | E34: =A34&C34&D34 -> 2014호9 | J34: 84A | K34: 455
A35: 201 | B35: 1001 | C35: =RIGHT(B35,1)&"호" -> 1호 | D35: =LEFT(B35,2) -> 10 | E35: =A35&C35&D35 -> 2011호10 | J35: 84B | K35: 355
A36: 201 | B36: 1002 | C36: =RIGHT(B36,1)&"호" -> 2호 | D36: =LEFT(B36,2) -> 10 | E36: =A36&C36&D36 -> 2012호10 | J36: 110A | K36: 192
A37: 201 | B37: 1003 | C37: =RIGHT(B37,1)&"호" -> 3호 | D37: =LEFT(B37,2) -> 10 | E37: =A37&C37&D37 -> 2013호10 | J37: 110B | K37: 179
A38: 201 | B38: 1004 | C38: =RIGHT(B38,1)&"호" -> 4호 | D38: =LEFT(B38,2) -> 10 | E38: =A38&C38&D38 -> 2014호10 | K38: =SUM(K32:K37) -> 1470
A39: 201 | B39: 1101 | C39: =RIGHT(B39,1)&"호" -> 1호 | D39: =LEFT(B39,2) -> 11 | E39: =A39&C39&D39 -> 2011호11
A40: 201 | B40: 1102 | C40: =RIGHT(B40,1)&"호" -> 2호 | D40: =LEFT(B40,2) -> 11 | E40: =A40&C40&D40 -> 2012호11
...
